Workbook
Name Set: 'LISTAS'!$A$2:$A$5
Name ControleJogo: 'LISTAS'!$B$2:$B$9
Name Equipes: 'LISTAS'!$C$2:$C$12
Name Posse: 'LISTAS'!$D$2:$D$3
Name FaseJogo: 'LISTAS'!$E$2:$E$9
Name Sistemas: 'LISTAS'!$F$2:$F$42
Name LadoAcao: =LISTAS!$H$2:$H$9
Name Atletas: =LISTAS!$J$2:$J$14
Name Goleiras: =LISTAS!$K$2:$K$3
Name FuncoesAtaque: =LISTAS!$L$2:$L$8
Name FuncoesDefesa: =LISTAS!$M$2:$M$5
Name Categorias: =LISTAS!$O$2:$O$7
Name AcoesAtaque: =LISTAS!$P$2:$P$76
Name AcoesDefesa: =LISTAS!$S$2:$S$79
Name AcoesGoleira: =LISTAS!$T$2:$T$11
Name Reposicao: =LISTAS!$U$2:$U$15
Name ResultadoColetivo: =LISTAS!$V$2:$V$21
Name ResultadoIndividual: =LISTAS!$W$2:$W$9
Name Analise: =LISTAS!$X$2:$X$5
Name Revisar: =LISTAS!$Y$2:$Y$3

Sheet SCOUT
A1: SCOUT V_1.1 — Handebol de Praia
A2: Uma linha = um evento. 4 blocos de ataque + 3 blocos de defesa, com função, categoria, ação e resultado individual.
A4: ID Evento | B4: Tempo de jogo | C4: Set | D4: Controle do jogo | E4: Placar CEPRAEA | F4: Placar adversário | G4: Diferença no placar | H4: Situação do placar | I4: Equipe analisada | J4: Adversário | K4: Posse de bola | L4: Fase do jogo | M4: Sistema | N4: Lado da ação | O4: Goleira | P4: Reposição | Q4: Atleta Ataque 1 | R4: Função Ataque 1 | S4: Categoria Ataque 1 | T4: Ação Ataque 1 | U4: Resultado Ind. Atq 1 | V4: Atleta Ataque 2 | W4: Função Ataque 2 | X4: Categoria Ataque 2 | Y4: Ação Ataque 2 | Z4: Resultado Ind. Atq 2 | AA4: Atleta Ataque 3 | AB4: Função Ataque 3 | AC4: Categoria Ataque 3 | AD4: Ação Ataque 3 | AE4: Resultado Ind. Atq 3 | AF4: Atleta Ataque 4 | AG4: Função Ataque 4 | AH4: Categoria Ataque 4 | AI4: Ação Ataque 4 | AJ4: Resultado Ind. Atq 4 | AK4: Atleta Defesa 1 | AL4: Função Defesa 1 | AM4: Categoria Defesa 1 | AN4: Ação Defesa 1 | AO4: Resultado Ind. Def 1 | AP4: Atleta Defesa 2 | AQ4: Função Defesa 2 | AR4: Categoria Defesa 2 | AS4: Ação Defesa 2 | AT4: Resultado Ind. Def 2 | AU4: Atleta Defesa 3 | AV4: Função Defesa 3 | AW4: Categoria Defesa 3 | AX4: Ação Defesa 3 | AY4: Resultado Ind. Def 3 | AZ4: Análise | BA4: Resultado coletivo | BB4: Observação | BC4: Revisar vídeo
A5: =ROW()-4 | B5: 00:14 | C5: 1º SET | D5: BOLA AO ALTO - INÍCIO | E5: 0 | F5: 0 | G5: =IF(OR(E5="",F5=""),"",E5-F5) | H5: =IF(G5="","",IF(G5>0,"Vencendo",IF(G5<0,"Perdendo","Empatado"))) | I5: CEPRAEA | J5: ADM Maricá | K5: CEPRAEA | L5: Ataque posicionado | M5: Ataque 3:1 ESP central + pivô destra | N5: Centro | O5: Carolina Bezerra | P5: Entrada da especialista | Q5: Bruna Xavier | R5: Central | S5: 1 - Ação técnica assertiva | T5: Passe para pivô em vantagem | U5: Acerto | V5: Marleide Nunes | W5: Pivô | X5: 1 - Ação técnica assertiva | Y5: Giro convertido | Z5: Acerto | AZ5: Positiva | BA5: Gol 2 pontos | BB5: Central fixou a base e pivô finalizou em giro. | BC5: Não
A6: =ROW()-4 | B6: 01:02 | C6: 1º SET | E6: 2 | F6: 0 | G6: =IF(OR(E6="",F6=""),"",E6-F6) | H6: =IF(G6="","",IF(G6>0,"Vencendo",IF(G6<0,"Perdendo","Empatado"))) | I6: CEPRAEA | J6: ADM Maricá | K6: Adversário | L6: Defesa posicionada | M6: Defesa API / Base / Solta | N6: Área | AK6: Gabi Peixinho | AL6: Base | AM6: 5 - Recuperação / ação defensiva positiva | AN6: Interceptação de passe | AO6: Recuperação defensiva | AP6: Rafaela Dillmann | AQ6: API | AR6: 1 - Ação técnica assertiva | AS6: Fechamento da linha de passe para pivô | AT6: Acerto | AU6: Carolina Peixinho | AV6: Solta | AW6: 1 - Ação técnica assertiva | AX6: Pressão correta na primeira linha | AY6: Acerto | AZ6: Positiva | BA6: Recuperação de bola | BB6: Base antecipou passe central após pressão da solta. | BC6: Não
A7: =ROW()-4 | G7: =IF(OR(E7="",F7=""),"",E7-F7) | H7: =IF(G7="","",IF(G7>0,"Vencendo",IF(G7<0,"Perdendo","Empatado")))
A8: =ROW()-4 | G8: =IF(OR(E8="",F8=""),"",E8-F8) | H8: =IF(G8="","",IF(G8>0,"Vencendo",IF(G8<0,"Perdendo","Empatado")))
A9: =ROW()-4 | G9: =IF(OR(E9="",F9=""),"",E9-F9) | H9: =IF(G9="","",IF(G9>0,"Vencendo",IF(G9<0,"Perdendo","Empatado")))
A10: =ROW()-4 | G10: =IF(OR(E10="",F10=""),"",E10-F10) | H10: =IF(G10="","",IF(G10>0,"Vencendo",IF(G10<0,"Perdendo","Empatado")))
A11: =ROW()-4 | G11: =IF(OR(E11="",F11=""),"",E11-F11) | H11: =IF(G11="","",IF(G11>0,"Vencendo",IF(G11<0,"Perdendo","Empatado")))
A12: =ROW()-4 | G12: =IF(OR(E12="",F12=""),"",E12-F12) | H12: =IF(G12="","",IF(G12>0,"Vencendo",IF(G12<0,"Perdendo","Empatado")))
A13: =ROW()-4 | G13: =IF(OR(E13="",F13=""),"",E13-F13) | H13: =IF(G13="","",IF(G13>0,"Vencendo",IF(G13<0,"Perdendo","Empatado")))
A14: =ROW()-4 | G14: =IF(OR(E14="",F14=""),"",E14-F14) | H14: =IF(G14="","",IF(G14>0,"Vencendo",IF(G14<0,"Perdendo","Empatado")))
A15: =ROW()-4 | G15: =IF(OR(E15="",F15=""),"",E15-F15) | H15: =IF(G15="","",IF(G15>0,"Vencendo",IF(G15<0,"Perdendo","Empatado")))
A16: =ROW()-4 | G16: =IF(OR(E16="",F16=""),"",E16-F16) | H16: =IF(G16="","",IF(G16>0,"Vencendo",IF(G16<0,"Perdendo","Empatado")))
A17: =ROW()-4 | G17: =IF(OR(E17="",F17=""),"",E17-F17) | H17: =IF(G17="","",IF(G17>0,"Vencendo",IF(G17<0,"Perdendo","Empatado")))
A18: =ROW()-4 | G18: =IF(OR(E18="",F18=""),"",E18-F18) | H18: =IF(G18="","",IF(G18>0,"Vencendo",IF(G18<0,"Perdendo","Empatado")))
... A104: =ROW()-4 | G104: =IF(OR(E104="",F104=""),"",E104-F104) | H104: =IF(G104="","",IF(G104>0,"Vencendo",IF(G104<0,"Perdendo","Empatado")))

Sheet LISTAS
A1: Set | B1: Controle do Jogo | C1: Equipes | D1: Posse | E1: Fase Jogo CEPRAEA | F1: Sistema Tático CEPRAEA | G1: Sistema Tático ADVERSÁRIO | H1: Funções Ataque Adversário | I1: Adversário Nº | J1: Atletas | K1: Goleiras | L1: FuncoesAtaque | M1: Posições Defensivas | N1: Posições Defensivas | O1: Categorias | P1: AcoesAtaque | Q1: Especialista central | R1: Tipo de Passe | S1: AcoesDefesa | T1: AcoesGoleira | U1: Reposicao | V1: ResultadoColetivo | W1: ResultadoIndividual | X1: Analise | Y1: Revisar
A2: 1º SET | B2: PEDIDO DE TEMPO TÉCNICO | C2: CEPRAEA | D2: CEPRAEA | E2: Ataque posicionado | F2: Ataque 3:1 ESP central + pivô destra | G2: Ataque 3:1 ESP central + pivô destra | H2: Central | J2: Aline Mello | K2: Carolina Bezerra | L2: Central | M2: Base | N2: Base | O2: 1 - Ação técnica assertiva | P2: Recepção segura na lateral esquerda | Q2: Passe de central com quebra para lateral esqeuerda | R2: Giro | S2: Posicionamento central correto | T2: Defesa de arremesso de 1 ponto | V2: Gol 1 ponto | W2: Acerto | X2: Positiva | Y2: Sim
A3: 2º SET | B3: RETORNO DO TEMPO TÉCNICO | C3: ADM Maricá | D3: Adversário | E3: Defesa posicionada | F3: Ataque 3:1 ESP central + pivô canhota | G3: Ataque 3:1 ESP central + pivô canhota | H3: Lateral esquerda | J3: Roberta Hernandez | K3: Paola Wolff | L3: Lateral esquerda | M3: Solta | N3: Solta | O3: 2 - Erro técnico | P3: Finalização de 1 ponto convertida | Q3: Passe de central do chão para giro da lateral esquerda | R3: Giro | S3: Comunicação defensiva efetiva | T3: Defesa de arremesso de 2 pontos | U3: Troca lado direito | V3: Gol 2 pontos | W3: Erro técnico | X3: Neutra | Y3: Não
A4: GOLDEN GOL | B4: BOLA AO ALTO - INÍCIO | C4: Campinas 360 | E4: Transição ofensiva | F4: Ataque 3:1 ESP lat direita canhota | G4: Ataque 3:1 ESP lat direita canhota | H4: Lateral Esquerda Especialista | J4: Carolina Peixinho | L4: Lateral Esquerda Especialista | M4: Atras da Pivô | N4: Atras da Pivô | O4: 3 - Assistência / ação que gera finalização | P4: Finalização de 2 pontos convertida | Q4: Passe de central saltando para giro da lateral esquerda | R4: Giro | S4: Leitura correta da especialista central | T4: Passe de saída correto | U4: Troca lado esquerdo | V4: Gol sofrido 1 ponto | W4: Assistência | X4: Negativa
A5: SHOOT OUT | B5: GOLDEN GOL | C5: Niterói Rugby | E5: Transição defensiva | F5: Ataque 3:1 ESP lat direita destra | G5: Ataque 3:1 ESP lat direita destra | H5: Pivô | J5: Gabriela Peixinho | L5: Pivô | M5: Goleira | N5: Goleira | O5: 4 - Erro de decisão | P5: Arremesso em giro convertido | Q5: Passe de central do chão após finta de passe para giro da lateral esquerda | R5: Giro | S5: Leitura correta da pivô | T5: Passe longo para transição | U5: Entrada da especialista | V5: Gol sofrido 2 pontos | W5: Erro de decisão | X5: Revisar
B6: FIM DO SET | C6: NR Beach | E6: Shoot-out | F6: Ataque 4:0 ESP lat esquerda | G6: Ataque 4:0 ESP lat esquerda | H6: Central Especialista | J6: Aline Kécia | L6: Central Especialista | M6: Avançada | N6: Avançada | O6: 5 - Recuperação / ação defensiva positiva | P6: Arremesso em aérea convertido | Q6: Passe de central saltando para aérea da lateral esquerda | R6: aérea | S6: Fechamento do centro | T6: Passe errado na saída | U6: Saída da goleira | V6: Defesa da goleira | W6: Recuperação defensiva
B7: FIM DO JOGO | C7: Rio Handbeach | E7: Golden Gol | F7: Ataque 4:0 ESP lat direita destra | G7: Ataque 4:0 ESP lat direita destra | H7: Central Playmaker Esq | J7: Bruna Xavier | L7: Central Playmaker Esq | O7: 6 - Falta / infração / ação irregular | P7: Infiltração pelo lado esquerdo com vantagem | Q7: Passe de central do chão para giro da lateral direita | R7: aérea | S7: Fechamento da linha da área | T7: Defesa no shoot-out | U7: Entrada defensiva | V7: Finalização para fora | W7: Infração
C8: IDEC | F8: Ataque 4:0 ESP lat direita canhota | G8: Ataque 4:0 ESP lat direita canhota | H8: Central Playmaker Dir | J8: Beatriz Correia | L8: Central Playmaker Dir | O8: 7 - Boa tomada de decisão | P8: Ataque ao espaço vazio da defesa | Q8: Passe de central saltando para giro da lateral direita | S8: Cobertura da API | T8: Gol de goleira | U8: Saída defensiva | V8: Finalização bloqueada | W8: Neutro
C9: América FC/ADHFT | F9: Ataque 4:0 ESP central esquerda | G9: Ataque 4:0 ESP central esquerda | H9: Lateral Direita Especialista | J9: Fernanda Campbell | L9: Lateral Direita Especialista | O9: 8 - Passe de apoio | P9: Finta curta para ganhar ângulo | Q9: Passe de central do chão após finta de passe para giro da lateral direita | S9: Cobertura da solta | T9: Erro de posicionamento | U9: Reposição rápida | V9: Perda de bola | W9: Revisar
C10: MHB — Milka Handbeach | F10: Ataque 4:0 ESP central direita canhota | G10: Ataque 4:0 ESP central direita canhota | H10: Lateral direita | J10: Marleide Nunes | L10: Lateral direita | O10: 9 - Desmarque | P10: Passe rápido para continuidade do ataque | Q10: Passe de central saltando para aérea da lateral direita | R10: aérea | S10: Troca de marcação correta | T10: Reposição rápida | U10: Reposição lenta | V10: Recuperação de bola
C11: Buds Handbeach | F11: Ataque 4:0 ESP central direita destra | G11: Ataque 4:0 ESP central direita destra | H11: Goleira passadora | J11: Rafaela Dillmann | L11: Goleira passadora | P11: Passe longo correto para lado oposto | Q11: Passe de central sem olhar para lateral esquerda | R11: aérea | S11: Flutuação entre pivô e especialista | T11: Reposição lenta | U11: Reposição direta | V11: Falta de ataque
C12: APCEF | F12: Defesa 3x0 | G12: Defesa 3x0 | J12: Taís Almeida | P12: Passe para pivô em condição de finalização | Q12: Passe de central sem olhar para lateral direita | R12: aérea | S12: Indução do ataque para lateral | U12: Reposição indireta | V12: Falta defensiva
F13: Defesa 2x1 | G13: Defesa 2x1 | P13: Passe para especialista em condição de finalização | Q13: Passe de central sem olhar para pivô | R13: aérea | S13: Temporização da atacante com bola | U13: Erro de substituição | V13: Tiro de 6m a favor
F14: Defesa 0x3 | G14: Defesa 0x3 | P14: Troca de posição correta com a central | Q14: Passe de central para aérea da pivô | R14: aérea | S14: Bloqueio de arremesso | U14: Atraso na troca | V14: Tiro de 6m contra
F15: Defesa 1x2 | G15: Defesa 1x2 | P15: Troca de posição correta com a pivô | Q15: Passe de central para giro da pivô | R15: Giro | S15: Bloqueio após giro | U15: Entrada correta da especialista | V15: Exclusão a favor
F16: Defesa individual | G16: Defesa individual | P16: Fixação da defensora antes do passe | Q16: Passe de central para especialista em vantagem | S16: Bloqueio duplo correto | V16: Exclusão contra
F17: Defesa mista | G17: Defesa mista | P17: Leitura correta do bloqueio defensivo | Q17: Passe de central após fixar a Base | S17: Antecipação de passe central | V17: Shoot-out convertido
F18: Defesa API / Base / Solta | G18: Defesa API / Base / Solta | P18: Finalização com bom ângulo | Q18: Passe de central após atrair a Solta | S18: Pressão controlada sem abrir o centro | V18: Shoot-out perdido
F19: Transição ofensiva direta 1x0 lat esquerda | G19: Transição ofensiva direta 1x0 lat esquerda | P19: Ataque em superioridade bem executado | Q19: Passe de central após deslocar a API | S19: Recuperação defensiva após perda | V19: Erro de substituição
F20: Transição ofensiva direta 1x0 lat esquerda + central | G20: Transição ofensiva direta 1x0 lat esquerda + central | P20: Continuidade após pressão defensiva | Q20: Finta de passe e passe para aérea | S20: Pressão correta na primeira linha | V20: Sem finalização
F21: Transição ofensiva direta 1x0 lat esquerda + central + pivô + lat direita | G21: Transição ofensiva direta 1x0 lat esquerda + central + pivô + lat direita | P21: Tomada de decisão rápida na transição | Q21: Finta de passe e passe para giro | S21: Entrada correta na linha de passe | V21: Revisar
F22: Transição ofensiva direta 2x1 lat direita | G22: Transição ofensiva direta 2x1 lat direita | P22: Recepção segura na lateral direita | Q22: Finta de arremesso e passe para pivô | S22: Antecipação de passe
F23: Transição ofensiva direta 2x1 lat direita + central | G23: Transição ofensiva direta 2x1 lat direita + central | P23: Ataque ao espaço entre base e API | Q23: Finta de arremesso e passe para lateral | S23: Interceptação de passe
F24: Transição ofensiva direta 2x1 lat esquerda | G24: Transição ofensiva direta 2x1 lat esquerda | P24: Ataque ao espaço entre base e solta | Q24: Passe longo da central para lado oposto | S24: Dissuasão na lateral
F25: Transição ofensiva indireta 3:1 ESP central | G25: Transição ofensiva indireta 3:1 ESP central | P25: Passe correto para pivô | Q25: Passe curto da central para pivô | S25: Dissuasão na central
F26: Transição ofensiva indireta 3:1 ESP lat esquerda | G26: Transição ofensiva indireta 3:1 ESP lat esquerda | P26: Passe correto para especialista | Q26: Passe em suspensão para finalização de 2 pontos | S26: Pressão na playmaker
F27: Transição ofensiva indireta 3:1 ESP lat direita | G27: Transição ofensiva indireta 3:1 ESP lat direita | P27: Passe correto para central | Q27: Passe picado para giro | S27: Recuo no tempo correto
F28: Transição ofensiva indireta 4:0 ESP lat esquerda | G28: Transição ofensiva indireta 4:0 ESP lat esquerda | P28: Posicionamento correto entre defensoras | Q28: Passe atrasado para finalização da especialista | S28: Subida no tempo correto
F29: Transição ofensiva indireta 4:0 ESP lat direita | G29: Transição ofensiva indireta 4:0 ESP lat direita | P29: Recepção segura próxima à área | Q29: Passe para lateral após troca de posição | S29: Leitura correta do lado da troca
F30: Transição ofensiva indireta 4:0 ESP central esquerda | G30: Transição ofensiva indireta 4:0 ESP central esquerda | P30: Recepção aérea correta | Q30: Passe para ataque ao espaço livre | S30: Indução ao passe longo
F31: Transição ofensiva indireta 4:0 ESP central direita | G31: Transição ofensiva indireta 4:0 ESP central direita | P31: Giro convertido | Q31: Passe que quebra a defesa 3x0 | S31: Indução ao erro técnico
F32: Transição defensiva direta 2x1 | G32: Transição defensiva direta 2x1 | P32: Aérea convertida | Q32: Passe que quebra a defesa 2x1 | S32: Fechamento da linha de passe para especialista
F33: Transição defensiva direta 3x0 - 1ª Base | G33: Transição defensiva direta 3x0 - 1ª Base | P33: Proteção da bola sem falta | Q33: Passe que gera gol de 2 pontos | S33: Marcação indireta da especialista
... F42: Shoot-out defensivo | G42: Shoot-out defensivo | P42: Passe aéreo correto | Q42: Erro de leitura da defesa | S42: Proteção contra aérea
P43: Controle de ritmo do ataque | Q43: Erro de decisão após finta | S43: Erro de posicionamento central
P44: Chamada correta do sistema | S44: Saiu do centro sem cobertura
P45: Erro de recepção | S45: Perdeu a especialista
P46: Passe errado | S46: Perdeu a pivô
P47: Passe interceptado | S47: Chegou atrasada no bloqueio
P48: Arremesso para fora | S48: Falhou na comunicação
...

Sheet BASE_ATLETAS_EVENTOS
A1: ID Evento | B1: Tempo de jogo | C1: Set | D1: Equipe analisada | E1: Adversário | F1: Posse de bola | G1: Fase do jogo | H1: Sistema | I1: Lado da ação | J1: Atleta | K1: Bloco | L1: Função | M1: Categoria | N1: Ação | O1: Resultado individual | P1: Análise | Q1: Resultado coletivo | R1: Observação
A3: Base normalizada por atleta/ação. Use esta aba para tabela dinâmica; a fórmula dinâmica pode ser ativada no Excel 365 conforme necessidade.

Sheet RESUMO
A1: RESUMO AUTOMÁTICO — Indicadores do jogo
A3: Total eventos | C3: Gols 1P | E3: Gols 2P | G3: Recuperações
A4: =COUNTA(SCOUT!A5:A104) | C4: =COUNTIF(SCOUT!BA5:BA104,"Gol 1 ponto") | E4: =COUNTIF(SCOUT!BA5:BA104,"Gol 2 pontos") | G4: =COUNTIF(SCOUT!BA5:BA104,"Recupera&#231;&#227;o de bola")
A6: Erros técnicos | C6: Assistências | E6: Infrações | G6: Revisar
A7: =COUNTIF(BASE_ATLETAS_EVENTOS!M:M,"2 - Erro t&#233;cnico") | C7: =COUNTIF(BASE_ATLETAS_EVENTOS!M:M,"3 - Assist&#234;ncia / a&#231;&#227;o que gera finaliza&#231;&#227;o") | E7: =COUNTIF(BASE_ATLETAS_EVENTOS!M:M,"6 - Falta / infra&#231;&#227;o / a&#231;&#227;o irregular") | G7: =COUNTIF(SCOUT!BC5:BC104,"Sim")+COUNTIF(SCOUT!AZ5:AZ104,"Revisar")
A11: Indicadores por Atleta
A12: Atleta | B12: Total ações | C12: Acertos | D12: Erros técnicos | E12: Assistências | F12: Erros decisão | G12: Recuperações | H12: Infrações
A13: Aline Mello | B13: =COUNTIF(BASE_ATLETAS_EVENTOS!J:J,A13) | C13: =COUNTIFS(BASE_ATLETAS_EVENTOS!J:J,A13,BASE_ATLETAS_EVENTOS!M:M,"1 - A&#231;&#227;o t&#233;cnica assertiva") | D13: =COUNTIFS(BASE_ATLETAS_EVENTOS!J:J,A13,BASE_ATLETAS_EVENTOS!M:M,"2 - Erro t&#233;cnico") | E13: =COUNTIFS(BASE_ATLETAS_EVENTOS!J:J,A13,BASE_ATLETAS_EVENTOS!M:M,"3 - Assist&#234;ncia / a&#231;&#227;o que gera finaliza&#231;&#227;o") | F13: =COUNTIFS(BASE_ATLETAS_EVENTOS!J:J,A13,BASE_ATLETAS_EVENTOS!M:M,"4 - Erro de decis&#227;o") | G13: =COUNTIFS(BASE_ATLETAS_EVENTOS!J:J,A13,BASE_ATLETAS_EVENTOS!M:M,"5 - Recupera&#231;&#227;o / a&#231;&#227;o defensiva positiva") | H13: =COUNTIFS(BASE_ATLETAS_EVENTOS!J:J,A13,BASE_ATLETAS_EVENTOS!M:M,"6 - Falta / infra&#231;&#227;o / a&#231;&#227;o irregular")
A14: Roberta Hernandez | B14: =COUNTIF(BASE_ATLETAS_EVENTOS!J:J,A14) | C14: =COUNTIFS(BASE_ATLETAS_EVENTOS!J:J,A14,BASE_ATLETAS_EVENTOS!M:M,"1 - A&#231;&#227;o t&#233;cnica assertiva") | D14: =COUNTIFS(BASE_ATLETAS_EVENTOS!J:J,A14,BASE_ATLETAS_EVENTOS!M:M,"2 - Erro t&#233;cnico") | E14: =COUNTIFS(BASE_ATLETAS_EVENTOS!J:J,A14,BASE_ATLETAS_EVENTOS!M:M,"3 - Assist&#234;ncia / a&#231;&#227;o que gera finaliza&#231;&#227;o") | F14: =COUNTIFS(BASE_ATLETAS_EVENTOS!J:J,A14,BASE_ATLETAS_EVENTOS!M:M,"4 - Erro de decis&#227;o") | G14: =COUNTIFS(BASE_ATLETAS_EVENTOS!J:J,A14,BASE_ATLETAS_EVENTOS!M:M,"5 - Recupera&#231;&#227;o / a&#231;&#227;o defensiva positiva") | H14: =COUNTIFS(BASE_ATLETAS_EVENTOS!J:J,A14,BASE_ATLETAS_EVENTOS!M:M,"6 - Falta / infra&#231;&#227;o / a&#231;&#227;o irregular")
A15: Carolina Peixinho | B15: =COUNTIF(BASE_ATLETAS_EVENTOS!J:J,A15) | C15: =COUNTIFS(BASE_ATLETAS_EVENTOS!J:J,A15,BASE_ATLETAS_EVENTOS!M:M,"1 - A&#231;&#227;o t&#233;cnica assertiva") | D15: =COUNTIFS(BASE_ATLETAS_EVENTOS!J:J,A15,BASE_ATLETAS_EVENTOS!M:M,"2 - Erro t&#233;cnico") | E15: =COUNTIFS(BASE_ATLETAS_EVENTOS!J:J,A15,BASE_ATLETAS_EVENTOS!M:M,"3 - Assist&#234;ncia / a&#231;&#227;o que gera finaliza&#231;&#227;o") | F15: =COUNTIFS(BASE_ATLETAS_EVENTOS!J:J,A15,BASE_ATLETAS_EVENTOS!M:M,"4 - Erro de decis&#227;o") | G15: =COUNTIFS(BASE_ATLETAS_EVENTOS!J:J,A15,BASE_ATLETAS_EVENTOS!M:M,"5 - Recupera&#231;&#227;o / a&#231;&#227;o defensiva positiva") | H15: =COUNTIFS(BASE_ATLETAS_EVENTOS!J:J,A15,BASE_ATLETAS_EVENTOS!M:M,"6 - Falta / infra&#231;&#227;o / a&#231;&#227;o irregular")
A16: Gabriela Peixinho | B16: =COUNTIF(BASE_ATLETAS_EVENTOS!J:J,A16) | C16: =COUNTIFS(BASE_ATLETAS_EVENTOS!J:J,A16,BASE_ATLETAS_EVENTOS!M:M,"1 - A&#231;&#227;o t&#233;cnica assertiva") | D16: =COUNTIFS(BASE_ATLETAS_EVENTOS!J:J,A16,BASE_ATLETAS_EVENTOS!M:M,"2 - Erro t&#233;cnico") | E16: =COUNTIFS(BASE_ATLETAS_EVENTOS!J:J,A16,BASE_ATLETAS_EVENTOS!M:M,"3 - Assist&#234;ncia / a&#231;&#227;o que gera finaliza&#231;&#227;o") | F16: =COUNTIFS(BASE_ATLETAS_EVENTOS!J:J,A16,BASE_ATLETAS_EVENTOS!M:M,"4 - Erro de decis&#227;o") | G16: =COUNTIFS(BASE_ATLETAS_EVENTOS!J:J,A16,BASE_ATLETAS_EVENTOS!M:M,"5 - Recupera&#231;&#227;o / a&#231;&#227;o defensiva positiva") | H16: =COUNTIFS(BASE_ATLETAS_EVENTOS!J:J,A16,BASE_ATLETAS_EVENTOS!M:M,"6 - Falta / infra&#231;&#227;o / a&#231;&#227;o irregular")
A17: Aline Kécia | B17: =COUNTIF(BASE_ATLETAS_EVENTOS!J:J,A17) | C17: =COUNTIFS(BASE_ATLETAS_EVENTOS!J:J,A17,BASE_ATLETAS_EVENTOS!M:M,"1 - A&#231;&#227;o t&#233;cnica assertiva") | D17: =COUNTIFS(BASE_ATLETAS_EVENTOS!J:J,A17,BASE_ATLETAS_EVENTOS!M:M,"2 - Erro t&#233;cnico") | E17: =COUNTIFS(BASE_ATLETAS_EVENTOS!J:J,A17,BASE_ATLETAS_EVENTOS!M:M,"3 - Assist&#234;ncia / a&#231;&#227;o que gera finaliza&#231;&#227;o") | F17: =COUNTIFS(BASE_ATLETAS_EVENTOS!J:J,A17,BASE_ATLETAS_EVENTOS!M:M,"4 - Erro de decis&#227;o") | G17: =COUNTIFS(BASE_ATLETAS_EVENTOS!J:J,A17,BASE_ATLETAS_EVENTOS!M:M,"5 - Recupera&#231;&#227;o / a&#231;&#227;o defensiva positiva") | H17: =COUNTIFS(BASE_ATLETAS_EVENTOS!J:J,A17,BASE_ATLETAS_EVENTOS!M:M,"6 - Falta / infra&#231;&#227;o / a&#231;&#227;o irregular")
A18: Bruna Xavier | B18: =COUNTIF(BASE_ATLETAS_EVENTOS!J:J,A18) | C18: =COUNTIFS(BASE_ATLETAS_EVENTOS!J:J,A18,BASE_ATLETAS_EVENTOS!M:M,"1 - A&#231;&#227;o t&#233;cnica assertiva") | D18: =COUNTIFS(BASE_ATLETAS_EVENTOS!J:J,A18,BASE_ATLETAS_EVENTOS!M:M,"2 - Erro t&#233;cnico") | E18: =COUNTIFS(BASE_ATLETAS_EVENTOS!J:J,A18,BASE_ATLETAS_EVENTOS!M:M,"3 - Assist&#234;ncia / a&#231;&#227;o que gera finaliza&#231;&#227;o") | F18: =COUNTIFS(BASE_ATLETAS_EVENTOS!J:J,A18,BASE_ATLETAS_EVENTOS!M:M,"4 - Erro de decis&#227;o") | G18: =COUNTIFS(BASE_ATLETAS_EVENTOS!J:J,A18,BASE_ATLETAS_EVENTOS!M:M,"5 - Recupera&#231;&#227;o / a&#231;&#227;o defensiva positiva") | H18: =COUNTIFS(BASE_ATLETAS_EVENTOS!J:J,A18,BASE_ATLETAS_EVENTOS!M:M,"6 - Falta / infra&#231;&#227;o / a&#231;&#227;o irregular")
A19: Beatriz Correia | B19: =COUNTIF(BASE_ATLETAS_EVENTOS!J:J,A19) | C19: =COUNTIFS(BASE_ATLETAS_EVENTOS!J:J,A19,BASE_ATLETAS_EVENTOS!M:M,"1 - A&#231;&#227;o t&#233;cnica assertiva") | D19: =COUNTIFS(BASE_ATLETAS_EVENTOS!J:J,A19,BASE_ATLETAS_EVENTOS!M:M,"2 - Erro t&#233;cnico") | E19: =COUNTIFS(BASE_ATLETAS_EVENTOS!J:J,A19,BASE_ATLETAS_EVENTOS!M:M,"3 - Assist&#234;ncia / a&#231;&#227;o que gera finaliza&#231;&#227;o") | F19: =COUNTIFS(BASE_ATLETAS_EVENTOS!J:J,A19,BASE_ATLETAS_EVENTOS!M:M,"4 - Erro de decis&#227;o") | G19: =COUNTIFS(BASE_ATLETAS_EVENTOS!J:J,A19,BASE_ATLETAS_EVENTOS!M:M,"5 - Recupera&#231;&#227;o / a&#231;&#227;o defensiva positiva") | H19: =COUNTIFS(BASE_ATLETAS_EVENTOS!J:J,A19,BASE_ATLETAS_EVENTOS!M:M,"6 - Falta / infra&#231;&#227;o / a&#231;&#227;o irregular")
A20: Fernanda Campbell | B20: =COUNTIF(BASE_ATLETAS_EVENTOS!J:J,A20) | C20: =COUNTIFS(BASE_ATLETAS_EVENTOS!J:J,A20,BASE_ATLETAS_EVENTOS!M:M,"1 - A&#231;&#227;o t&#233;cnica assertiva") | D20: =COUNTIFS(BASE_ATLETAS_EVENTOS!J:J,A20,BASE_ATLETAS_EVENTOS!M:M,"2 - Erro t&#233;cnico") | E20: =COUNTIFS(BASE_ATLETAS_EVENTOS!J:J,A20,BASE_ATLETAS_EVENTOS!M:M,"3 - Assist&#234;ncia / a&#231;&#227;o que gera finaliza&#231;&#227;o") | F20: =COUNTIFS(BASE_ATLETAS_EVENTOS!J:J,A20,BASE_ATLETAS_EVENTOS!M:M,"4 - Erro de decis&#227;o") | G20: =COUNTIFS(BASE_ATLETAS_EVENTOS!J:J,A20,BASE_ATLETAS_EVENTOS!M:M,"5 - Recupera&#231;&#227;o / a&#231;&#227;o defensiva positiva") | H20: =COUNTIFS(BASE_ATLETAS_EVENTOS!J:J,A20,BASE_ATLETAS_EVENTOS!M:M,"6 - Falta / infra&#231;&#227;o / a&#231;&#227;o irregular")
A21: Marleide Nunes | B21: =COUNTIF(BASE_ATLETAS_EVENTOS!J:J,A21) | C21: =COUNTIFS(BASE_ATLETAS_EVENTOS!J:J,A21,BASE_ATLETAS_EVENTOS!M:M,"1 - A&#231;&#227;o t&#233;cnica assertiva") | D21: =COUNTIFS(BASE_ATLETAS_EVENTOS!J:J,A21,BASE_ATLETAS_EVENTOS!M:M,"2 - Erro t&#233;cnico") | E21: =COUNTIFS(BASE_ATLETAS_EVENTOS!J:J,A21,BASE_ATLETAS_EVENTOS!M:M,"3 - Assist&#234;ncia / a&#231;&#227;o que gera finaliza&#231;&#227;o") | F21: =COUNTIFS(BASE_ATLETAS_EVENTOS!J:J,A21,BASE_ATLETAS_EVENTOS!M:M,"4 - Erro de decis&#227;o") | G21: =COUNTIFS(BASE_ATLETAS_EVENTOS!J:J,A21,BASE_ATLETAS_EVENTOS!M:M,"5 - Recupera&#231;&#227;o / a&#231;&#227;o defensiva positiva") | H21: =COUNTIFS(BASE_ATLETAS_EVENTOS!J:J,A21,BASE_ATLETAS_EVENTOS!M:M,"6 - Falta / infra&#231;&#227;o / a&#231;&#227;o irregular")
A22: Rafaela Dillmann | B22: =COUNTIF(BASE_ATLETAS_EVENTOS!J:J,A22) | C22: =COUNTIFS(BASE_ATLETAS_EVENTOS!J:J,A22,BASE_ATLETAS_EVENTOS!M:M,"1 - A&#231;&#227;o t&#233;cnica assertiva") | D22: =COUNTIFS(BASE_ATLETAS_EVENTOS!J:J,A22,BASE_ATLETAS_EVENTOS!M:M,"2 - Erro t&#233;cnico") | E22: =COUNTIFS(BASE_ATLETAS_EVENTOS!J:J,A22,BASE_ATLETAS_EVENTOS!M:M,"3 - Assist&#234;ncia / a&#231;&#227;o que gera finaliza&#231;&#227;o") | F22: =COUNTIFS(BASE_ATLETAS_EVENTOS!J:J,A22,BASE_ATLETAS_EVENTOS!M:M,"4 - Erro de decis&#227;o") | G22: =COUNTIFS(BASE_ATLETAS_EVENTOS!J:J,A22,BASE_ATLETAS_EVENTOS!M:M,"5 - Recupera&#231;&#227;o / a&#231;&#227;o defensiva positiva") | H22: =COUNTIFS(BASE_ATLETAS_EVENTOS!J:J,A22,BASE_ATLETAS_EVENTOS!M:M,"6 - Falta / infra&#231;&#227;o / a&#231;&#227;o irregular")
A23: Taís Almeida | B23: =COUNTIF(BASE_ATLETAS_EVENTOS!J:J,A23) | C23: =COUNTIFS(BASE_ATLETAS_EVENTOS!J:J,A23,BASE_ATLETAS_EVENTOS!M:M,"1 - A&#231;&#227;o t&#233;cnica assertiva") | D23: =COUNTIFS(BASE_ATLETAS_EVENTOS!J:J,A23,BASE_ATLETAS_EVENTOS!M:M,"2 - Erro t&#233;cnico") | E23: =COUNTIFS(BASE_ATLETAS_EVENTOS!J:J,A23,BASE_ATLETAS_EVENTOS!M:M,"3 - Assist&#234;ncia / a&#231;&#227;o que gera finaliza&#231;&#227;o") | F23: =COUNTIFS(BASE_ATLETAS_EVENTOS!J:J,A23,BASE_ATLETAS_EVENTOS!M:M,"4 - Erro de decis&#227;o") | G23: =COUNTIFS(BASE_ATLETAS_EVENTOS!J:J,A23,BASE_ATLETAS_EVENTOS!M:M,"5 - Recupera&#231;&#227;o / a&#231;&#227;o defensiva positiva") | H23: =COUNTIFS(BASE_ATLETAS_EVENTOS!J:J,A23,BASE_ATLETAS_EVENTOS!M:M,"6 - Falta / infra&#231;&#227;o / a&#231;&#227;o irregular")
A24: Carolina Bezerra | B24: =COUNTIF(BASE_ATLETAS_EVENTOS!J:J,A24) | C24: =COUNTIFS(BASE_ATLETAS_EVENTOS!J:J,A24,BASE_ATLETAS_EVENTOS!M:M,"1 - A&#231;&#227;o t&#233;cnica assertiva") | D24: =COUNTIFS(BASE_ATLETAS_EVENTOS!J:J,A24,BASE_ATLETAS_EVENTOS!M:M,"2 - Erro t&#233;cnico") | E24: =COUNTIFS(BASE_ATLETAS_EVENTOS!J:J,A24,BASE_ATLETAS_EVENTOS!M:M,"3 - Assist&#234;ncia / a&#231;&#227;o que gera finaliza&#231;&#227;o") | F24: =COUNTIFS(BASE_ATLETAS_EVENTOS!J:J,A24,BASE_ATLETAS_EVENTOS!M:M,"4 - Erro de decis&#227;o") | G24: =COUNTIFS(BASE_ATLETAS_EVENTOS!J:J,A24,BASE_ATLETAS_EVENTOS!M:M,"5 - Recupera&#231;&#227;o / a&#231;&#227;o defensiva positiva") | H24: =COUNTIFS(BASE_ATLETAS_EVENTOS!J:J,A24,BASE_ATLETAS_EVENTOS!M:M,"6 - Falta / infra&#231;&#227;o / a&#231;&#227;o irregular")
A25: Paola Wolff | B25: =COUNTIF(BASE_ATLETAS_EVENTOS!J:J,A25) | C25: =COUNTIFS(BASE_ATLETAS_EVENTOS!J:J,A25,BASE_ATLETAS_EVENTOS!M:M,"1 - A&#231;&#227;o t&#233;cnica assertiva") | D25: =COUNTIFS(BASE_ATLETAS_EVENTOS!J:J,A25,BASE_ATLETAS_EVENTOS!M:M,"2 - Erro t&#233;cnico") | E25: =COUNTIFS(BASE_ATLETAS_EVENTOS!J:J,A25,BASE_ATLETAS_EVENTOS!M:M,"3 - Assist&#234;ncia / a&#231;&#227;o que gera finaliza&#231;&#227;o") | F25: =COUNTIFS(BASE_ATLETAS_EVENTOS!J:J,A25,BASE_ATLETAS_EVENTOS!M:M,"4 - Erro de decis&#227;o") | G25: =COUNTIFS(BASE_ATLETAS_EVENTOS!J:J,A25,BASE_ATLETAS_EVENTOS!M:M,"5 - Recupera&#231;&#227;o / a&#231;&#227;o defensiva positiva") | H25: =COUNTIFS(BASE_ATLETAS_EVENTOS!J:J,A25,BASE_ATLETAS_EVENTOS!M:M,"6 - Falta / infra&#231;&#227;o / a&#231;&#227;o irregular")
A29: Eficiência por Fase do Jogo
A30: Fase | B30: Eventos | C30: Gols a favor | D30: Erros/perdas | E30: Eficiência gols
A31: Ataque posicionado | B31: =COUNTIF(SCOUT!L:L,A31) | C31: =COUNTIFS(SCOUT!L:L,A31,SCOUT!BA:BA,"Gol 1 ponto")+COUNTIFS(SCOUT!L:L,A31,SCOUT!BA:BA,"Gol 2 pontos") | D31: =COUNTIFS(SCOUT!L:L,A31,SCOUT!BA:BA,"Perda de bola")+COUNTIFS(SCOUT!L:L,A31,SCOUT!BA:BA,"Erro de substitui&#231;&#227;o") | E31: =IFERROR(C31/B31,0)
A32: Defesa posicionada | B32: =COUNTIF(SCOUT!L:L,A32) | C32: =COUNTIFS(SCOUT!L:L,A32,SCOUT!BA:BA,"Gol 1 ponto")+COUNTIFS(SCOUT!L:L,A32,SCOUT!BA:BA,"Gol 2 pontos") | D32: =COUNTIFS(SCOUT!L:L,A32,SCOUT!BA:BA,"Perda de bola")+COUNTIFS(SCOUT!L:L,A32,SCOUT!BA:BA,"Erro de substitui&#231;&#227;o") | E32: =IFERROR(C32/B32,0)
A33: Transição ofensiva direta | B33: =COUNTIF(SCOUT!L:L,A33) | C33: =COUNTIFS(SCOUT!L:L,A33,SCOUT!BA:BA,"Gol 1 ponto")+COUNTIFS(SCOUT!L:L,A33,SCOUT!BA:BA,"Gol 2 pontos") | D33: =COUNTIFS(SCOUT!L:L,A33,SCOUT!BA:BA,"Perda de bola")+COUNTIFS(SCOUT!L:L,A33,SCOUT!BA:BA,"Erro de substitui&#231;&#227;o") | E33: =IFERROR(C33/B33,0)
A34: Transição ofensiva indireta | B34: =COUNTIF(SCOUT!L:L,A34) | C34: =COUNTIFS(SCOUT!L:L,A34,SCOUT!BA:BA,"Gol 1 ponto")+COUNTIFS(SCOUT!L:L,A34,SCOUT!BA:BA,"Gol 2 pontos") | D34: =COUNTIFS(SCOUT!L:L,A34,SCOUT!BA:BA,"Perda de bola")+COUNTIFS(SCOUT!L:L,A34,SCOUT!BA:BA,"Erro de substitui&#231;&#227;o") | E34: =IFERROR(C34/B34,0)
A35: Transição defensiva direta | B35: =COUNTIF(SCOUT!L:L,A35) | C35: =COUNTIFS(SCOUT!L:L,A35,SCOUT!BA:BA,"Gol 1 ponto")+COUNTIFS(SCOUT!L:L,A35,SCOUT!BA:BA,"Gol 2 pontos") | D35: =COUNTIFS(SCOUT!L:L,A35,SCOUT!BA:BA,"Perda de bola")+COUNTIFS(SCOUT!L:L,A35,SCOUT!BA:BA,"Erro de substitui&#231;&#227;o") | E35: =IFERROR(C35/B35,0)
A36: Transição defensiva indireta | B36: =COUNTIF(SCOUT!L:L,A36) | C36: =COUNTIFS(SCOUT!L:L,A36,SCOUT!BA:BA,"Gol 1 ponto")+COUNTIFS(SCOUT!L:L,A36,SCOUT!BA:BA,"Gol 2 pontos") | D36: =COUNTIFS(SCOUT!L:L,A36,SCOUT!BA:BA,"Perda de bola")+COUNTIFS(SCOUT!L:L,A36,SCOUT!BA:BA,"Erro de substitui&#231;&#227;o") | E36: =IFERROR(C36/B36,0)
A37: Shoot-out | B37: =COUNTIF(SCOUT!L:L,A37) | C37: =COUNTIFS(SCOUT!L:L,A37,SCOUT!BA:BA,"Gol 1 ponto")+COUNTIFS(SCOUT!L:L,A37,SCOUT!BA:BA,"Gol 2 pontos") | D37: =COUNTIFS(SCOUT!L:L,A37,SCOUT!BA:BA,"Perda de bola")+COUNTIFS(SCOUT!L:L,A37,SCOUT!BA:BA,"Erro de substitui&#231;&#227;o") | E37: =IFERROR(C37/B37,0)
A38: Controle de jogo | B38: =COUNTIF(SCOUT!L:L,A38) | C38: =COUNTIFS(SCOUT!L:L,A38,SCOUT!BA:BA,"Gol 1 ponto")+COUNTIFS(SCOUT!L:L,A38,SCOUT!BA:BA,"Gol 2 pontos") | D38: =COUNTIFS(SCOUT!L:L,A38,SCOUT!BA:BA,"Perda de bola")+COUNTIFS(SCOUT!L:L,A38,SCOUT!BA:BA,"Erro de substitui&#231;&#227;o") | E38: =IFERROR(C38/B38,0)

Sheet DASHBOARD
A1: DASHBOARD — SCOUT HANDEBOL DE PRAIA
A2: Painel de leitura rápida com indicadores, gráficos e resumo visual.
A4: Eventos | D4: Gols 2P | G4: Recuperações | J4: Revisar
A5: =RESUMO!B4 | D5: =RESUMO!F4 | G5: =RESUMO!H4 | J5: =RESUMO!H7
A8: Ações por atleta
A9: =RESUMO!A12 | B9: =RESUMO!B12 | C9: =RESUMO!C12 | D9: =RESUMO!D12 | E9: =RESUMO!E12 | F9: =RESUMO!F12 | G9: =RESUMO!G12 | H9: =RESUMO!H12
A10: =RESUMO!A13 | B10: =RESUMO!B13 | C10: =RESUMO!C13 | D10: =RESUMO!D13 | E10: =RESUMO!E13 | F10: =RESUMO!F13 | G10: =RESUMO!G13 | H10: =RESUMO!H13
A11: =RESUMO!A14 | B11: =RESUMO!B14 | C11: =RESUMO!C14 | D11: =RESUMO!D14 | E11: =RESUMO!E14 | F11: =RESUMO!F14 | G11: =RESUMO!G14 | H11: =RESUMO!H14
A12: =RESUMO!A15 | B12: =RESUMO!B15 | C12: =RESUMO!C15 | D12: =RESUMO!D15 | E12: =RESUMO!E15 | F12: =RESUMO!F15 | G12: =RESUMO!G15 | H12: =RESUMO!H15
A13: =RESUMO!A16 | B13: =RESUMO!B16 | C13: =RESUMO!C16 | D13: =RESUMO!D16 | E13: =RESUMO!E16 | F13: =RESUMO!F16 | G13: =RESUMO!G16 | H13: =RESUMO!H16
A14: =RESUMO!A17 | B14: =RESUMO!B17 | C14: =RESUMO!C17 | D14: =RESUMO!D17 | E14: =RESUMO!E17 | F14: =RESUMO!F17 | G14: =RESUMO!G17 | H14: =RESUMO!H17
A15: =RESUMO!A18 | B15: =RESUMO!B18 | C15: =RESUMO!C18 | D15: =RESUMO!D18 | E15: =RESUMO!E18 | F15: =RESUMO!F18 | G15: =RESUMO!G18 | H15: =RESUMO!H18
A16: =RESUMO!A19 | B16: =RESUMO!B19 | C16: =RESUMO!C19 | D16: =RESUMO!D19 | E16: =RESUMO!E19 | F16: =RESUMO!F19 | G16: =RESUMO!G19 | H16: =RESUMO!H19
A17: =RESUMO!A20 | B17: =RESUMO!B20 | C17: =RESUMO!C20 | D17: =RESUMO!D20 | E17: =RESUMO!E20 | F17: =RESUMO!F20 | G17: =RESUMO!G20 | H17: =RESUMO!H20
A18: =RESUMO!A21 | B18: =RESUMO!B21 | C18: =RESUMO!C21 | D18: =RESUMO!D21 | E18: =RESUMO!E21 | F18: =RESUMO!F21 | G18: =RESUMO!G21 | H18: =RESUMO!H21
A19: =RESUMO!A22 | B19: =RESUMO!B22 | C19: =RESUMO!C22 | D19: =RESUMO!D22 | E19: =RESUMO!E22 | F19: =RESUMO!F22 | G19: =RESUMO!G22 | H19: =RESUMO!H22
A20: =RESUMO!A23 | B20: =RESUMO!B23 | C20: =RESUMO!C23 | D20: =RESUMO!D23 | E20: =RESUMO!E23 | F20: =RESUMO!F23 | G20: =RESUMO!G23 | H20: =RESUMO!H23
... A22: =RESUMO!A25 | B22: =RESUMO!B25 | C22: =RESUMO!C25 | D22: =RESUMO!D25 | E22: =RESUMO!E25 | F22: =RESUMO!F25 | G22: =RESUMO!G25 | H22: =RESUMO!H25

Sheet LEGENDA
A1: LEGENDA E CRITÉRIOS DE ACEITE — SCOUT V_1.1
A3: Categoria | B3: Descrição | C3: Uso
A4: 1 | B4: Ação técnica assertiva | C4: Execução correta, vantagem criada ou manutenção da posse.
A5: 2 | B5: Erro técnico | C5: Falha de execução.
A6: 3 | B6: Assistência / ação que gera finalização | C6: Passe, bloqueio ou fixação que gera finalização.
A7: 4 | B7: Erro de decisão | C7: Escolha ruim ou leitura equivocada.
A8: 5 | B8: Recuperação / ação defensiva positiva | C8: Interceptação, bloqueio, indução de erro.
A9: 6 | B9: Falta / infração / ação irregular | C9: Contato, invasão, tiro de 6m, troca irregular.
A11: Checklist dos 35 ajustes implementados
A12: 1 | B12: Versão nova SCOUTV_1.1 criada. | C12: Implementado
A13: 2 | B13: Base principal sem espelhamento. | C13: Implementado
A14: 3 | B14: ID Evento. | C14: Implementado
A15: 4 | B15: Tempo de jogo. | C15: Implementado
A16: 5 | B16: Set separado. | C16: Implementado
A17: 6 | B17: Controle com lista. | C17: Implementado
A18: 7 | B18: Placar CEPRAEA separado. | C18: Implementado
A19: 8 | B19: Diferença calculada. | C19: Implementado
A20: 9 | B20: Situação do placar calculada. | C20: Implementado
A21: 10 | B21: Equipe analisada e adversário. | C21: Implementado
A22: 11 | B22: Posse de bola. | C22: Implementado
A23: 12 | B23: Fase do jogo reduzida. | C23: Implementado
... A46: 35 | B46: Aba RESUMO/DASHBOARD. | C46: Implementado
